Workbook
Name Category: #REF!
Name Category: #REF!
Name Category: #REF!
Name Category: #REF!
Name Category: #REF!
Name Category: #REF!
Name Category: #REF!
Name Category: #REF!
Name Category: #REF!
Name Category: #REF!
Name Category: #REF!

Sheet Cover
C2: TEST CASE
B4: Project Name | C4: Tìm kiếm việc làm | F4: Creator | G4: Việt
B5: Project Code | F5: Reviewer/Approver
B6: Document Code | F6: Issue Date
F7: Version
B10: Record of change
B11: Change Date | C11: Change Item | D11: Change description | E11: ID Name | F11: Note

Sheet TestReport
B1: TEST REPORT
B3: Project Name | C3: Tìm kiếm việc làm | E3: Creator | G3: Việt
B4: Project Code | E4: Reviewer/Approver
B5: Document Code | E5: Issue Date
B6: Notes
B10: No | C10: Test Items | D10: Pass | E10: Fail | F10: NT | G10: N/A | H10: Number of test cases
B11: 1 | C11: Đăng ký ứng viên | D11: ='Đăng ký ứng viên'!A5 -> 8 | E11: ='Đăng ký ứng viên'!B5 -> 10 | F11: ='Đăng ký ứng viên'!C5 -> 0 | G11: ='Đăng ký ứng viên'!D5 -> 0 | H11: =SUM(D11:G11) -> 18
B12: 2 | C12: Đăng ký nhà tuyển dụng | D12: ='Đăng ký nhà tuyển dụng'!A5 -> 6 | E12: ='Đăng ký nhà tuyển dụng'!B5 -> 9 | F12: ='Đăng ký nhà tuyển dụng'!C5 -> 0 | G12: ='Đăng ký nhà tuyển dụng'!D5 -> 1 | H12: =SUM(D12:G12) -> 16
B13: 3 | C13: Đăng nhập hệ thống | D13: ='Đăng nhập hệ thống'!A5 -> 14 | E13: ='Đăng nhập hệ thống'!B5 -> 13 | F13: ='Đăng nhập hệ thống'!C5 -> 7 | G13: ='Đăng nhập hệ thống'!D5 -> 6 | H13: =SUM(D13:G13) -> 40
B14: 4 | C14: Đăng xuất tài khoản | D14: ='Đăng xuất tài khoản'!A5 -> 2 | E14: ='Đăng xuất tài khoản'!B5 -> 0 | F14: ='Đăng xuất tài khoản'!C5 -> 0 | G14: ='Đăng xuất tài khoản'!D5 -> 1 | H14: =SUM(D14:G14) -> 3
B15: 5 | C15: Đăng bài tìm ứng viên | D15: ='Đăng bài tìm ứng viên'!A5 -> 6 | E15: ='Đăng bài tìm ứng viên'!B5 -> 1 | F15: ='Đăng bài tìm ứng viên'!C5 -> 0 | G15: ='Đăng bài tìm ứng viên'!D5 -> 0 | H15: =SUM(D15:G15) -> 7
B16: 6 | C16: Sửa xóa bài đăng việc làm | D16: ='Sửa Xóa bài Đăng việc làm'!A5 -> 1 | E16: ='Sửa Xóa bài Đăng việc làm'!B5 -> 3 | F16: ='Sửa Xóa bài Đăng việc làm'!C5 -> 0 | G16: ='Sửa Xóa bài Đăng việc làm'!D5 -> 3 | H16: =SUM(D16:G16) -> 7
B17: 7 | C17: Xem thông tin ứng viên đã ứng tuyển | D17: ='Xem ứng viên ứng tuyển'!A5 -> 1 | E17: ='Xem ứng viên ứng tuyển'!B5 -> 1 | F17: ='Xem ứng viên ứng tuyển'!C5 -> 0 | G17: ='Xem ứng viên ứng tuyển'!D5 -> 0 | H17: =SUM(D17:G17) -> 2
B18: 8 | C18: Ứng tuyển công việc | D18: ='Ứng tuyển công việc'!A5 -> 2 | E18: ='Ứng tuyển công việc'!B5 -> 3 | F18: ='Ứng tuyển công việc'!C5 -> 0 | G18: ='Ứng tuyển công việc'!D5 -> 1 | H18: =SUM(D18:G18) -> 6
B19: 9 | C19: Chỉnh sửa hồ sơ ứng viên | D19: ='Chỉnh sửa hồ sơ ứng viên'!A5 -> 4 | E19: ='Chỉnh sửa hồ sơ ứng viên'!B5 -> 2 | F19: ='Chỉnh sửa hồ sơ ứng viên'!C5 -> 0 | G19: ='Chỉnh sửa hồ sơ ứng viên'!D5 -> 0 | H19: =SUM(D19:G19) -> 6
B20: 10 | C20: Ứng viên đăng bài | D20: ='Ứng viên đăng bài'!A5 -> 4 | E20: ='Ứng viên đăng bài'!B5 -> 1 | F20: ='Ứng viên đăng bài'!C5 -> 0 | G20: ='Ứng viên đăng bài'!D5 -> 0 | H20: =SUM(D20:G20) -> 5
C26: Sub total | D26: =SUM(D11:D17) -> 38 | E26: =SUM(E11:E17) -> 37 | F26: =SUM(F11:F17) -> 7 | G26: =SUM(G11:G17) -> 11 | H26: =SUM(H11:H17) -> 93
C28: Test coverage | E28: =($D26+$E26)*100/$H26 -> 80.645161 | F28: %
C29: Test successful coverage | E29: =$D26*100/($D26+$G26) -> 77.55102 | F29: %
B43: {=+B43:B45} -> #REF!

Sheet Đăng ký ứng viên
A1: Item Test | B1: UC01
A2: Test requirement | B2: Ensure that all features listed below work properly without any errors when using the below browsers. - Edge in latest version - Google Chrome in latest version
A3: Tester | B3: Việt
A4: Pass | B4: Fail | C4: NT | D4: N/A | E4: Number of Test cases
A5: =COUNTIF(F:F,"Pass") -> 8 | B5: =COUNTIF(F:F,"Fail") -> 10 | C5: =COUNTIF(F:F,"Untested") -> 0 | D5: =COUNTIF(F:F,"N/A") -> 0 | E5: =SUM(A5:D5) -> 18
A6: % | B6: % | C6: % | D6: %
A8: ID | B8: Test Case Description | C8: Pre-condition | D8: Test Case Procedure | E8: Expected Output | F8: Result | G8: Test date | H8: Tester | I8: Note
B9: 1.1. Kiểm tra giao diện
A10: =IF(AND(E10=""),"","["&TEXT($B$1,"##")&"-"&TEXT(ROW()-9-COUNTBLANK($E$8:E9)+1,"##")&"]") -> [UC01-1] | B10: Kiểm tra tổng quan màn hình Đăng ký ứng viên | C10: Truy cập vào hệ thống http://34.143.239.189/ | D10: 1. Vào trang đăng nhập và đăng ký. 2. Chọn đăng kí dành cho ứng viên | E10: Màn hình hiển thị đầy đủ các field gồm: - Icon: Avatar - Button: Chọn tệp - Icon: Họ và tên, Số điện thoại, Kĩ năng, Email, Ngày Sinh, Ngoại ngữ, Tài khoản, Kinh nghiệm, Học vấn, Mật khẩu, Giới thiệu bản thân - Textbox: Họ và tên, Số điện thoại, Kĩ năng, Email, Ngày Sinh, Ngoại ngữ, Tài khoản, Kinh nghiệm, Học vấn, Mật khẩu, Giới thiệu bản thân - Radio button: Nam, nữ - Button: Chọn tệp, Đăng ký, Đăng nhập ngay | F10: Pass | G10: 17/04/2024 | H10: =B3 -> Việt
A11: =IF(AND(E11=""),"","["&TEXT($B$1,"##")&"-"&TEXT(ROW()-9-COUNTBLANK($E$8:E10)+1,"##")&"]") -> [UC01-2] | B11: Kiểm tra chi tiết các button | C11: Truy cập vào hệ thống http://34.143.239.189/ | D11: 1. Vào trang đăng nhập và đăng ký. 2. Chọn đăng kí dành cho ứng viên | E11: Cho phép click vào các button | F11: Pass | G11: 17/04/2024 | H11: =B3 -> Việt
A12: =IF(AND(E12=""),"","["&TEXT($B$1,"##")&"-"&TEXT(ROW()-9-COUNTBLANK($E$8:E11)+1,"##")&"]") -> [UC01-3] | B12: Kiểm tra chi tiết các textbox | C12: Truy cập vào hệ thống http://34.143.239.189/ | D12: 1. Vào trang đăng nhập và đăng ký. 2. Chọn đăng kí dành cho ứng viên | E12: - Watermark ứng với các field - Cho phép nhập thông tin vào field | F12: Pass | G12: 17/04/2024 | H12: =B3 -> Việt
A13: =IF(AND(E13=""),"","["&TEXT($B$1,"##")&"-"&TEXT(ROW()-9-COUNTBLANK($E$8:E12)+1,"##")&"]") -> [UC01-4] | B13: Kiểm tra các Radio buton | C13: Truy cập vào hệ thống http://34.143.239.189/ | D13: 1. Vào trang đăng nhập và đăng ký. 2. Chọn đăng kí dành cho ứng viên | E13: Cho phép click vào các Radio button | F13: Pass | G13: 17/04/2024 | H13: =B3 -> Việt
A14: =IF(AND(E14=""),"","["&TEXT($B$1,"##")&"-"&TEXT(ROW()-9-COUNTBLANK($E$8:E13)+1,"##")&"]") -> [UC01-5] | B14: Kiểm tra các Icon | C14: Truy cập vào hệ thống http://34.143.239.189/ | D14: 1. Vào trang đăng nhập và đăng ký. 2. Chọn đăng kí dành cho ứng viên | E14: Các icon ứng với các field ở màn hình theo yêu cầu | F14: Pass | G14: 17/04/2024 | H14: =B3 -> Việt
B15: 1.2. Kiểm tra chức năng
A16: =IF(AND(E16=""),"","["&TEXT($B$1,"##")&"-"&TEXT(ROW()-9-COUNTBLANK($E$8:E15)+1,"##")&"]") -> [UC01-6] | B16: Kiểm tra bỏ trống các trường bắt buộc | C16: Truy cập vào hệ thống http://34.143.239.189/ | D16: 1. Vào trang đăng nhập và đăng ký. 2. Chọn đăng kí dành cho ứng viên. 3. Nhập thông tin vào các textbox có ở màn hình nhưng bỏ trống các trường bắt buộc: Họ tên, số điện thoại, email, ngày sinh, giới tính 4. Chọn nút đăng ký | E16: - Không thể tạo Tài khoản vì không nhập thông tin bắt buộc - Đăng ký thất bại | F16: Pass | G16: 17/04/2024 | H16: =B3 -> Việt
A17: =IF(AND(E17=""),"","["&TEXT($B$1,"##")&"-"&TEXT(ROW()-9-COUNTBLANK($E$8:E16)+1,"##")&"]") -> [UC01-7] | B17: Kiểm tra bỏ trống các trường không bắt buộc | C17: Truy cập vào hệ thống http://34.143.239.189/ | D17: 1. Vào trang đăng nhập và đăng ký. 2. Chọn đăng kí dành cho ứng viên. 3. Nhập thông tin vào các textbox có ở màn hình nhưng bỏ trống các trường không bắt buộc 4. Chọn nút đăng ký | E17: Cho phép tạo tài khoản | F17: Fail | G17: 17/04/2024 | H17: =B3 -> Việt | I17: Hiện tại các trường không bắt buộc nhập lại bắt buộc phải nhập. EV: https://drive.google.com/file/d/18Oe8XZqrEzFYGj3tRzcjg_E2_C4fEV4d/view?usp=sharing
A18: =IF(AND(E18=""),"","["&TEXT($B$1,"##")&"-"&TEXT(ROW()-9-COUNTBLANK($E$8:E16)+1,"##")&"]") -> [UC01-8] | B18: Đăng ký với Tài khoản đã tồn tại | C18: Truy cập vào hệ thống http://34.143.239.189/ | D18: 1. Vào trang đăng nhập và đăng ký. 2. Chọn đăng kí dành cho ứng viên. 3. Nhập một tài khoản đã tồn tại 4. Chọn nút đăng ký | E18: Đăng ký không thành công và hiển thị thông báo "Tài khoản đã tồn tại" | F18: Fail | G18: 20/04/2024 | H18: =B3 -> Việt | I18: Vẫn có thể tạo TK đã tồn tại. EV: https://drive.google.com/file/d/1i8xdRqWumsJT1TroEgcI5l8DUbZrioXO/view?usp=sharing
A19: =IF(AND(E19=""),"","["&TEXT($B$1,"##")&"-"&TEXT(ROW()-9-COUNTBLANK($E$8:E18)+1,"##")&"]") -> [UC01-9] | B19: Đăng ký tài khoản với một Email đã tồn tại trên hệ thống | C19: Truy cập vào hệ thống http://34.143.239.189/ | D19: 1. Vào trang đăng nhập và đăng ký. 2. Chọn đăng kí dành cho ứng viên. 3. Tạo tài khoản với Email đã có trên hệ thống 4. Chọn nút đăng ký | E19: Đăng ký không thành công và hiển thị thông báo "Email đã tồn tại trên hệ thống" | F19: Fail | G19: 20/04/2024 | H19: =B3 -> Việt | I19: Vẫn có thể tạo TK đã tồn tại. EV: https://drive.google.com/file/d/1i8xdRqWumsJT1TroEgcI5l8DUbZrioXO/view?usp=sharing
A20: =IF(AND(E20=""),"","["&TEXT($B$1,"##")&"-"&TEXT(ROW()-9-COUNTBLANK($E$8:E19)+1,"##")&"]") -> [UC01-10] | B20: Nhập sai định dạng Email | C20: Truy cập vào hệ thống http://34.143.239.189/ | D20: 1. Vào trang đăng nhập và đăng ký. 2. Chọn đăng kí dành cho ứng viên. 3. Nhập thông tin vào các textbox có ở màn hình nhưng nhập sai định dạng email 4. Chọn nút đăng ký | E20: Đăng ký không thành công và hiển thị thông báo "Email hoặc Số điện thoại không hợp lệ" | F20: Pass | G20: 17/04/2024 | H20: =B3 -> Việt
A21: =IF(AND(E21=""),"","["&TEXT($B$1,"##")&"-"&TEXT(ROW()-9-COUNTBLANK($E$8:E20)+1,"##")&"]") -> [UC01-11] | B21: Đăng ký tài khoản với một Số điện thoại đã tồn tại trên hệ thống | C21: Truy cập vào hệ thống http://34.143.239.189/ | D21: 1. Vào trang đăng nhập và đăng ký. 2. Chọn đăng kí dành cho ứng viên. 3. Tạo tài khoản với Số điện thoại đã có trên hệ thống 4. Chọn nút đăng ký | E21: Đăng ký không thành công và hiển thị thông báo "Email đã tồn tại trên hệ thống" | F21: Fail | G21: 20/04/2024 | H21: =B3 -> Việt | I21: Vẫn có thể tạo TK đã tồn tại. EV: https://drive.google.com/file/d/1i8xdRqWumsJT1TroEgcI5l8DUbZrioXO/view?usp=sharing
A22: =IF(AND(E22=""),"","["&TEXT($B$1,"##")&"-"&TEXT(ROW()-9-COUNTBLANK($E$8:E21)+1,"##")&"]") -> [UC01-12] | B22: Nhập sai định dạng Số điện thoại | C22: Truy cập vào hệ thống http://34.143.239.189/ | D22: 1. Vào trang đăng nhập và đăng ký. 2. Chọn đăng kí dành cho ứng viên. 3. Nhập các trường có ở màn hình và sai định dạng SĐT 4. Chọn nút đăng ký | E22: Đăng ký không thành công và hiển thị thông báo "Email hoặc Số điện thoại không hợp lệ" | F22: Fail | G22: 17/04/2024 | H22: =B3 -> Việt | I22: Không hiển thị thông báo như yêu cầu. EV: https://drive.google.com/file/d/1eL4CVafKne6iodnGWI6_98eb8-NYZ7E7/view?usp=drive_link
A23: =IF(AND(E23=""),"","["&TEXT($B$1,"##")&"-"&TEXT(ROW()-9-COUNTBLANK($E$8:E22)+1,"##")&"]") -> [UC01-13] | B23: Nhập mật khẩu ít hơn 8 ký tự, có chữ hoa, thường, số và ký tự đặc biệt | C23: Truy cập vào hệ thống http://34.143.239.189/ | D23: 1. Vào trang đăng nhập và đăng ký. 2. Chọn đăng kí dành cho ứng viên. 3. Nhập mật khẩu ít hơn 8 ký tự 4. Chọn nút đăng ký | E23: Đăng ký không thành công và hiển thị thông báo “Mật khẩu không hợp lệ, mật khẩu phải tối thiểu 8 kí tự, bao gồm chữ hoa, thường, số và kí tự đặc biệt” | F23: Fail | G23: 17/04/2024 | H23: =B3 -> Việt | I23: Hiển thị sai câu thông báo và giới hạn ký tự không đúng như yêu cầu (Yêu cầu tối thiểu 8 ký tự nhưng hệ thống đang là 5) EV: https://drive.google.com/file/d/1zluaXb13DIEHXaYVELHW82WdkRJW2sfK/view?usp=drive_link
A24: =IF(AND(E24=""),"","["&TEXT($B$1,"##")&"-"&TEXT(ROW()-9-COUNTBLANK($E$8:E23)+1,"##")&"]") -> [UC01-14] | B24: Nhập mật khẩu thiếu chữ hoa, >= 8 ký tự, có chữ thường, số và ký tự đặc biệt | C24: Truy cập vào hệ thống http://34.143.239.189/ | D24: 1. Vào trang đăng nhập và đăng ký. 2. Chọn đăng kí dành cho ứng viên. 3. Nhập mật khẩu thiếu chữ hoa, >= 8 ký tự, có chữ thường, số và ký tự đặc biệt 4. Chọn nút đăng ký | E24: Đăng ký không thành công và hiển thị thông báo "“Mật khẩu không hợp lệ, mật khẩu phải tối thiểu 8 kí tự, bao gồm chữ hoa, thường, số và kí tự đặc biệt”" | F24: Fail | G24: 17/04/2024 | H24: =B3 -> Việt | I24: Không hiển thị thông báo như yêu cầu. EV: https://drive.google.com/file/d/1eL4CVafKne6iodnGWI6_98eb8-NYZ7E7/view?usp=drive_link
A25: =IF(AND(E25=""),"","["&TEXT($B$1,"##")&"-"&TEXT(ROW()-9-COUNTBLANK($E$8:E24)+1,"##")&"]") -> [UC01-15] | B25: Nhập mật khẩu thiếu chữ thường, >= 8 ký tự, có chữ hoa, số và ký tự đặc biệt | C25: Truy cập vào hệ thống http://34.143.239.189/ | D25: 1. Vào trang đăng nhập và đăng ký. 2. Chọn đăng kí dành cho ứng viên. 3. Nhập mật khẩu thiếu chữ thường, >= 8 ký tự, có chữ hoa, số và ký tự đặc biệt 4. Chọn nút đăng ký | E25: Đăng ký không thành công và hiển thị thông báo “Mật khẩu không hợp lệ, mật khẩu phải tối thiểu 8 kí tự, bao gồm chữ hoa, thường, số và kí tự đặc biệt” | F25: Fail | G25: 17/04/2024 | H25: =B3 -> Việt | I25: Không hiển thị thông báo như yêu cầu. EV: https://drive.google.com/file/d/1eL4CVafKne6iodnGWI6_98eb8-NYZ7E7/view?usp=drive_link
A26: =IF(AND(E26=""),"","["&TEXT($B$1,"##")&"-"&TEXT(ROW()-9-COUNTBLANK($E$8:E25)+1,"##")&"]") -> [UC01-16] | B26: Nhập mật khẩu thiếu chữ số , >= 8 ký tự, có chữ hoa, thường và ký tự đặc biệt | C26: Truy cập vào hệ thống http://34.143.239.189/ | D26: 1. Vào trang đăng nhập và đăng ký. 2. Chọn đăng kí dành cho ứng viên. 3. Nhập mật khẩu thiếu chữ số , >= 8 ký tự, có chữ hoa, thường và ký tự đặc biệt 4. Chọn nút đăng ký | E26: Đăng ký không thành công và hiển thị thông báo “Mật khẩu không hợp lệ, mật khẩu phải tối thiểu 8 kí tự, bao gồm chữ hoa, thường, số và kí tự đặc biệt” | F26: Fail | G26: 17/04/2024 | H26: =B3 -> Việt | I26: Không hiển thị thông báo như yêu cầu. EV: https://drive.google.com/file/d/1eL4CVafKne6iodnGWI6_98eb8-NYZ7E7/view?usp=drive_link
A27: =IF(AND(E27=""),"","["&TEXT($B$1,"##")&"-"&TEXT(ROW()-9-COUNTBLANK($E$8:E26)+1,"##")&"]") -> [UC01-17] | B27: Nhập mật khẩu thiếu ký tự đặc biệt, >= 8 ký tự, có chữ hoa, thường và chữ số | C27: Truy cập vào hệ thống http://34.143.239.189/ | D27: 1. Vào trang đăng nhập và đăng ký. 2. Chọn đăng kí dành cho ứng viên. 3. Nhập mật khẩu thiếu ký tự đặc biệt, >= 8 ký tự, có chữ hoa, thường và chữ số 4. Chọn nút đăng ký | E27: Đăng ký không thành công và hiển thị thông báo “Mật khẩu không hợp lệ, mật khẩu phải tối thiểu 8 kí tự, bao gồm chữ hoa, thường, số và kí tự đặc biệt” | F27: Fail | G27: 17/04/2024 | H27: =B3 -> Việt | I27: Không hiển thị thông báo như yêu cầu. EV: https://drive.google.com/file/d/1eL4CVafKne6iodnGWI6_98eb8-NYZ7E7/view?usp=drive_link
A28: =IF(AND(E28=""),"","["&TEXT($B$1,"##")&"-"&TEXT(ROW()-9-COUNTBLANK($E$8:E27)+1,"##")&"]") -> [UC01-18] | B28: Nhập thông tin đầy đủ, đúng định dạng và theo yêu cầu | C28: Truy cập vào hệ thống http://34.143.239.189/ | D28: 1. Vào trang đăng nhập và đăng ký. 2. Chọn đăng kí dành cho ứng viên. 3. Nhập thông tin có ở các field 4. Chọn nút đăng ký | E28: Hiển thị thông báo Đăng ký thành công và chuyển về trang đăng nhập | F28: Pass | G28: 17/04/2024 | H28: =B3 -> Việt

Sheet Đăng ký nhà tuyển dụng
A1: Item Test | B1: UC02
A2: Test requirement | B2: Ensure that all features listed below work properly without any errors when using the below browsers. - Edge in latest version - Google Chrome in latest version
A3: Tester | B3: Việt
A4: Pass | B4: Fail | C4: NT | D4: N/A | E4: Number of Test cases
A5: =COUNTIF(F:F,"Pass") -> 6 | B5: =COUNTIF(F:F,"Fail") -> 9 | C5: =COUNTIF(F:F,"Untested") -> 0 | D5: =COUNTIF(F:F,"N/A") -> 1 | E5: =SUM(A5:D5) -> 16
A6: % | B6: % | C6: % | D6: %
A8: ID | B8: Test Case Description | C8: Pre-condition | D8: Test Case Procedure | E8: Expected Output | F8: Result | G8: Test date | H8: Tester | I8: Note
B9: 1.1. Kiểm tra giao diện
A10: =IF(AND(E10=""),"","["&TEXT($B$1,"##")&"-"&TEXT(ROW()-9-COUNTBLANK($E$8:E9)+1,"##")&"]") -> [UC02-1] | B10: Kiểm tra tổng quan màn hình Đăng ký nhà tuyển dụng | C10: Truy cập vào hệ thống http://34.143.239.189/ | D10: 1. Vào trang đăng nhập và đăng ký. 2. Chọn đăng kí dành cho nhà tuyển dụng | E10: Màn hình hiển thị đầy đủ các field gồm: - Icon: Avatar - Button: Chọn tệp - Icon: Tên công ty, Email, Tài khoản, Mật khẩu, Website, Số điện thoại, Địa chỉ, Quốc gia - Textbox: Tên công ty, Email, Tài khoản, Mật khẩu, Website, Số điện thoại, Địa chỉ, Quốc gia - Button: Chọn tệp, Đăng ký, Đăng nhập ngay | F10: Pass | G10: 20/04/2024 | H10: =B3 -> Việt
A11: =IF(AND(E11=""),"","["&TEXT($B$1,"##")&"-"&TEXT(ROW()-9-COUNTBLANK($E$8:E10)+1,"##")&"]") -> [UC02-2] | B11: Kiểm tra chi tiết các button | C11: Truy cập vào hệ thống http://34.143.239.189/ | D11: 1. Vào trang đăng nhập và đăng ký. 2. Chọn đăng kí dành cho nhà tuyển dụng | E11: Cho phép click vào các button | F11: Pass | G11: 20/04/2024 | H11: =B3 -> Việt
A12: =IF(AND(E12=""),"","["&TEXT($B$1,"##")&"-"&TEXT(ROW()-9-COUNTBLANK($E$8:E11)+1,"##")&"]") -> [UC02-3] | B12: Kiểm tra chi tiết các textbox | C12: Truy cập vào hệ thống http://34.143.239.189/ | D12: 1. Vào trang đăng nhập và đăng ký. 2. Chọn đăng kí dành cho nhà tuyển dụng | E12: - Watermark ứng với các field - Cho phép nhập thông tin vào field | F12: Pass | G12: 20/04/2024 | H12: =B3 -> Việt
A13: =IF(AND(E13=""),"","["&TEXT($B$1,"##")&"-"&TEXT(ROW()-9-COUNTBLANK($E$8:E12)+1,"##")&"]") -> [UC02-4] | B13: Kiểm tra các Icon | C13: Truy cập vào hệ thống http://34.143.239.189/ | D13: 1. Vào trang đăng nhập và đăng ký. 2. Chọn đăng kí dành cho nhà tuyển dụng | E13: Các icon ứng với các field ở màn hình theo yêu cầu | F13: Pass | G13: 20/04/2024 | H13: =B3 -> Việt
B14: 1.2. Kiểm tra chức năng
A15: =IF(AND(E15=""),"","["&TEXT($B$1,"##")&"-"&TEXT(ROW()-9-COUNTBLANK($E$8:E14)+1,"##")&"]") -> [UC02-5] | B15: Kiểm tra bỏ trống các trường bắt buộc | C15: Truy cập vào hệ thống http://34.143.239.189/ | D15: 1. Vào trang đăng nhập và đăng ký. 2. Chọn đăng kí dành cho nhà tuyển dụng. 3. Nhập thông tin vào các textbox có ở màn hình nhưng bỏ trống các trường bắt buộc: Tên công ty, số điện thoại, email) 4. Chọn nút đăng ký | E15: - Không thể tạo Tài khoản vì không nhập thông tin bắt buộc - Đăng ký thất bại | F15: Pass | G15: 20/04/2024 | H15: =B3 -> Việt
A16: =IF(AND(E16=""),"","["&TEXT($B$1,"##")&"-"&TEXT(ROW()-9-COUNTBLANK($E$8:E15)+1,"##")&"]") -> [UC02-6] | B16: Đăng ký với Tài khoản đã tồn tại | C16: Truy cập vào hệ thống http://34.143.239.189/ | D16: 1. Vào trang đăng nhập và đăng ký. 2. Chọn đăng kí dành cho nhà tuyển dụng. 3. Nhập một tài khoản đã tồn tại 4. Chọn nút đăng ký | E16: Đăng ký không thành công và hiển thị thông báo "Tài khoản đã tồn tại" | F16: Fail | G16: 20/04/2024 | H16: =B3 -> Việt | I16: Vẫn có thể tạo tài khoản đã tồn tại
A17: =IF(AND(E17=""),"","["&TEXT($B$1,"##")&"-"&TEXT(ROW()-9-COUNTBLANK($E$8:E16)+1,"##")&"]") -> [UC02-7] | B17: Đăng ký tài khoản với một Email đã tồn tại trên hệ thống | C17: Truy cập vào hệ thống http://34.143.239.189/ | D17: 1. Vào trang đăng nhập và đăng ký. 2. Chọn đăng kí dành cho nhà tuyển dụng. 3. Tạo tài khoản với Email đã có trên hệ thống 4. Chọn nút đăng ký | E17: Đăng ký không thành công và hiển thị thông báo "Email đã tồn tại trên hệ thống" | F17: Fail | G17: 20/04/2024 | H17: =B3 -> Việt | I17: Vẫn có thể tạo email đã tồn tại
A18: =IF(AND(E18=""),"","["&TEXT($B$1,"##")&"-"&TEXT(ROW()-9-COUNTBLANK($E$8:E17)+1,"##")&"]") -> [UC02-8] | B18: Nhập sai định dạng Email | C18: Truy cập vào hệ thống http://34.143.239.189/ | D18: 1. Vào trang đăng nhập và đăng ký. 2. Chọn đăng kí dành cho nhà tuyển dụng. 3. Nhập thông tin vào các textbox có ở màn hình nhưng nhập sai định dạng email 4. Chọn nút đăng ký | E18: Đăng ký không thành công và hiển thị thông báo "Email hoặc Số điện thoại không hợp lệ" | F18: Fail | G18: 20/04/2024 | H18: =B3 -> Việt | I18: Hiển thị sai câu thông báo. EV: https://drive.google.com/file/d/1sKmkz-O1BaX1sZ8pUBNt5vYMTD-KGvSf/view?usp=drive_link
A19: =IF(AND(E19=""),"","["&TEXT($B$1,"##")&"-"&TEXT(ROW()-9-COUNTBLANK($E$8:E18)+1,"##")&"]") -> [UC02-9] | B19: Đăng ký tài khoản với một Số điện thoại đã tồn tại trên hệ thống | C19: Truy cập vào hệ thống http://34.143.239.189/ | D19: 1. Vào trang đăng nhập và đăng ký. 2. Chọn đăng kí dành cho nhà tuyển dụng. 3. Tạo tài khoản với Số điện thoại đã có trên hệ thống 4. Chọn nút đăng ký | E19: Đăng ký không thành công và hiển thị thông báo "Email đã tồn tại trên hệ thống" | F19: N/A | G19: 20/04/2024 | H19: =B3 -> Việt | I19: Chưa có tài khoản
A20: =IF(AND(E20=""),"","["&TEXT($B$1,"##")&"-"&TEXT(ROW()-9-COUNTBLANK($E$8:E19)+1,"##")&"]") -> [UC02-10] | B20: Nhập sai định dạng Số điện thoại | C20: Truy cập vào hệ thống http://34.143.239.189/ | D20: 1. Vào trang đăng nhập và đăng ký. 2. Chọn đăng kí dành cho nhà tuyển dụng. 3. Nhập vào textbox SĐT là chữ cái 4. Chọn nút đăng ký | E20: Đăng ký không thành công và hiển thị thông báo "Email hoặc Số điện thoại không hợp lệ" | F20: Fail | G20: 20/04/2024 | H20: =B3 -> Việt | I20: Đang cho phép nhập ký tự chữ EV: https://drive.google.com/file/d/166i0QwKtqhKaSxExwiSKvYjLZf0W8hDD/view?usp=drive_link
A21: =IF(AND(E21=""),"","["&TEXT($B$1,"##")&"-"&TEXT(ROW()-9-COUNTBLANK($E$8:E20)+1,"##")&"]") -> [UC02-11] | B21: Nhập mật khẩu ít hơn 8 ký tự, có chữ hoa, thường, số và ký tự đặc biệt | C21: Truy cập vào hệ thống http://34.143.239.189/ | D21: 1. Vào trang đăng nhập và đăng ký. 2. Chọn đăng kí dành cho nhà tuyển dụng. 3. Nhập mật khẩu ít hơn 8 ký tự, có chữ hoa, thường, số và ký tự đặc biệt 4. Chọn nút đăng ký | E21: Đăng ký không thành công và hiển thị thông báo "“Mật khẩu không hợp lệ, mật khẩu phải tối thiểu 8 kí tự, bao gồm chữ hoa, thường, số và kí tự đặc biệt”" | F21: Fail | G21: 20/04/2024 | H21: =B3 -> Việt | I21: Giới hạn mật khẩu không đúng, giới hạn phải là 8 EV: https://drive.google.com/file/d/1rGzMjV8vpODvwTo9U4DqpKg7zRwYVfHD/view?usp=drive_link
A22: =IF(AND(E22=""),"","["&TEXT($B$1,"##")&"-"&TEXT(ROW()-9-COUNTBLANK($E$8:E21)+1,"##")&"]") -> [UC02-12] | B22: Nhập mật khẩu thiếu chữ hoa, >= 8 ký tự, có chữ thường, số và ký tự đặc biệt | C22: Truy cập vào hệ thống http://34.143.239.189/ | D22: 1. Vào trang đăng nhập và đăng ký. 2. Chọn đăng kí dành cho nhà tuyển dụng. 3. Nhập mật khẩu thiếu chữ hoa, >= 8 ký tự, có chữ thường, số và ký tự đặc biệt 4. Chọn nút đăng ký | E22: Đăng ký không thành công và hiển thị thông báo "“Mật khẩu không hợp lệ, mật khẩu phải tối thiểu 8 kí tự, bao gồm chữ hoa, thường, số và kí tự đặc biệt”" | F22: Fail | G22: 20/04/2024 | H22: =B3 -> Việt | I22: Đang cho phép nhập thiếu chữ hoa: https://drive.google.com/file/d/1AkiS-hTyAaYdSFmzaAinnFZWuUg3LxIx/view?usp=drive_link
A23: =IF(AND(E23=""),"","["&TEXT($B$1,"##")&"-"&TEXT(ROW()-9-COUNTBLANK($E$8:E22)+1,"##")&"]") -> [UC02-13] | B23: Nhập mật khẩu thiếu chữ thường, >= 8 ký tự, có chữ hoa, số và ký tự đặc biệt | C23: Truy cập vào hệ thống http://34.143.239.189/ | D23: 1. Vào trang đăng nhập và đăng ký. 2. Chọn đăng kí dành cho nhà tuyển dụng. 3. Nhập mật khẩu thiếu chữ thường, >= 8 ký tự, có chữ hoa, số và ký tự đặc biệt 4. Chọn nút đăng ký | E23: Đăng ký không thành công và hiển thị thông báo “Mật khẩu không hợp lệ, mật khẩu phải tối thiểu 8 kí tự, bao gồm chữ hoa, thường, số và kí tự đặc biệt” | F23: Fail | G23: 20/04/2024 | H23: =B3 -> Việt | I23: Đang cho phép nhập thiếu chữ thường: https://drive.google.com/file/d/1AkiS-hTyAaYdSFmzaAinnFZWuUg3LxIx/view?usp=drive_link
A24: =IF(AND(E24=""),"","["&TEXT($B$1,"##")&"-"&TEXT(ROW()-9-COUNTBLANK($E$8:E23)+1,"##")&"]") -> [UC02-14] | B24: Nhập mật khẩu thiếu chữ số , >= 8 ký tự, có chữ hoa, thường và ký tự đặc biệt | C24: Truy cập vào hệ thống http://34.143.239.189/ | D24: 1. Vào trang đăng nhập và đăng ký. 2. Chọn đăng kí dành cho nhà tuyển dụng. 3. Nhập mật khẩu thiếu chữ số , >= 8 ký tự, có chữ hoa, thường và ký tự đặc biệt 4. Chọn nút đăng ký | E24: Đăng ký không thành công và hiển thị thông báo “Mật khẩu không hợp lệ, mật khẩu phải tối thiểu 8 kí tự, bao gồm chữ hoa, thường, số và kí tự đặc biệt” | F24: Fail | G24: 20/04/2024 | H24: =B3 -> Việt | I24: Đang cho phép nhập thiếu chữ số: https://drive.google.com/file/d/1AkiS-hTyAaYdSFmzaAinnFZWuUg3LxIx/view?usp=drive_link
A25: =IF(AND(E25=""),"","["&TEXT($B$1,"##")&"-"&TEXT(ROW()-9-COUNTBLANK($E$8:E24)+1,"##")&"]") -> [UC02-15] | B25: Nhập mật khẩu thiếu ký tự đặc biệt, >= 8 ký tự, có chữ hoa, thường và chữ số | C25: Truy cập vào hệ thống http://34.143.239.189/ | D25: 1. Vào trang đăng nhập và đăng ký. 2. Chọn đăng kí dành cho nhà tuyển dụng. 3. Nhập mật khẩu thiếu ký tự đặc biệt, >= 8 ký tự, có chữ hoa, thường và chữ số 4. Chọn nút đăng ký | E25: Đăng ký không thành công và hiển thị thông báo “Mật khẩu không hợp lệ, mật khẩu phải tối thiểu 8 kí tự, bao gồm chữ hoa, thường, số và kí tự đặc biệt” | F25: Fail | G25: 20/04/2024 | H25: =B3 -> Việt | I25: Đang cho phép nhập thiếu ký tự đặc biệt: https://drive.google.com/file/d/1AkiS-hTyAaYdSFmzaAinnFZWuUg3LxIx/view?usp=drive_link
A26: =IF(AND(E26=""),"","["&TEXT($B$1,"##")&"-"&TEXT(ROW()-9-COUNTBLANK($E$8:E25)+1,"##")&"]") -> [UC02-16] | B26: Nhập thông tin đầy đủ, đúng định dạng và theo yêu cầu | C26: Truy cập vào hệ thống http://34.143.239.189/ | D26: 1. Vào trang đăng nhập và đăng ký. 2. Chọn đăng kí dành cho nhà tuyển dụng. 3. Nhập thông tin có ở các field 4. Chọn nút đăng ký | E26: Hiển thị thông báo Đăng ký thành công và chuyển về trang đăng nhập | F26: Pass | G26: 20/04/2024 | H26: =B3 -> Việt

Sheet Sửa Xóa bài Đăng việc làm
A1: Item Test | B1: UC06
A2: Test requirement | B2: Ensure that all features listed below work properly without any errors when using the below browsers. - Edge in latest version - Google Chrome in latest version
A3: Tester | B3: Việt
A4: Pass | B4: Fail | C4: NT | D4: N/A | E4: Number of Test cases
A5: =COUNTIF(F:F,"Pass") -> 1 | B5: =COUNTIF(F:F,"Fail") -> 3 | C5: =COUNTIF(F:F,"Untested") -> 0 | D5: =COUNTIF(F:F,"N/A") -> 3 | E5: =SUM(A5:D5) -> 7
A6: % | B6: % | C6: % | D6: %
A8: ID | B8: Test Case Description | C8: Pre-condition | D8: Test Case Procedure | E8: Expected Output | F8: Result | G8: Test date | H8: Tester | I8: Note
B9: 1.1. Kiểm tra giao diện màn hình chỉnh sửa
A10: =IF(AND(E10=""),"","["&TEXT($B$1,"##")&"-"&TEXT(ROW()-9-COUNTBLANK($E$8:E9)+1,"##")&"]") -> [UC06-1] | B10: Kiểm tra tổng quan màn hình Chỉnh sửa thông tin | C10: - Truy cập vào hệ thống http://34.143.239.189/ - Bài tuyển dụng đã được tạo | D10: 1. Vào trang Tạo thông tin tuyển dụng 2. Click vào button cây viết ở bài đăng | E10: - Textbox: Màn hình hiển thị các trường thông tin của bài đăng ứng với trường tạo bài đăng - Button: Chỉnh sửa | F10: Fail | H10: =B3 -> Việt | I10: Icon/tên field không rõ ràng EV: https://drive.google.com/file/d/1Gai8tTA6_QT7E0WRX0CC5z4co0V21qHX/view?usp=drive_link
A11: =IF(AND(E11=""),"","["&TEXT($B$1,"##")&"-"&TEXT(ROW()-9-COUNTBLANK($E$8:E10)+1,"##")&"]") -> [UC06-2] | B11: Kiểm tra chi tiết các textbox | C11: - Truy cập vào hệ thống http://34.143.239.189/ - Bài tuyển dụng đã được tạo | D11: 1. Vào trang Tạo thông tin tuyển dụng 2. Click vào button cây viết ở bài đăng 3. Nhập thông tin ở các textbox | E11: - Cho phép nhập thông tin vào các textbox - Mặc định các thông tin hiển thị ở các textbox khi tạo bài đăng - Thông tin đúng với vị trí của các textbox | F11: N/A | H11: =B3 -> Việt | I11: Chưa test được vì thông tin ở các field không rõ ràng
A12: =IF(AND(E12=""),"","["&TEXT($B$1,"##")&"-"&TEXT(ROW()-9-COUNTBLANK($E$8:E11)+1,"##")&"]") -> [UC06-3] | B12: Kiểm tra chi tiết button Chỉnh sửa | C12: - Truy cập vào hệ thống http://34.143.239.189/ - Bài tuyển dụng đã được tạo | D12: 1. Vào trang Tạo thông tin tuyển dụng 2. Click vào button cây viết ở bài đăng 3. Nhập thông tin ở các textbox 4. Click vào button Chỉnh sửa | E12: Cho phép click vào button | F12: Pass | H12: =B3 -> Việt
B13: 1.2. Kiểm tra chức năng Chỉnh sửa
A14: =IF(AND(E14=""),"","["&TEXT($B$1,"##")&"-"&TEXT(ROW()-9-COUNTBLANK($E$8:E13)+1,"##")&"]") -> [UC06-4] | B14: Bỏ trống các trường bắt buộc | C14: - Truy cập vào hệ thống http://34.143.239.189/ - Bài tuyển dụng đã được tạo | D14: 1. Vào trang Tạo thông tin tuyển dụng 2. Click vào button cây viết ở bài đăng 3. Nhập thông tin ở các textbox nhưng bỏ trống các trường bắt buộc 4. Click vào button Chỉnh sửa | E14: Sửa thông tin thất bại và hiển thị thông báo “Có thể bạn nhập chưa đầy đủ hoặc sai thông tin” | F14: N/A | H14: =B3 -> Việt | I14: Chưa test được vì thông tin ở các field không rõ ràng
A15: =IF(AND(E15=""),"","["&TEXT($B$1,"##")&"-"&TEXT(ROW()-9-COUNTBLANK($E$8:E14)+1,"##")&"]") -> [UC06-5] | B15: Bỏ trống các trường không bắt buộc | C15: - Truy cập vào hệ thống http://34.143.239.189/ - Bài tuyển dụng đã được tạo | D15: 1. Vào trang Tạo thông tin tuyển dụng 2. Click vào button cây viết ở bài đăng 3. Nhập thông tin ở các trường bắt buộc và bỏ trống các textbox còn lại 4. Click vào button Chỉnh sửa | E15: - Chỉnh sửa thành công và hiển thị thông báo “Sửa thông tin thành công” | F15: N/A | H15: =B3 -> Việt | I15: Chưa test được vì thông tin ở các field không rõ ràng
A16: =IF(AND(E16=""),"","["&TEXT($B$1,"##")&"-"&TEXT(ROW()-9-COUNTBLANK($E$8:E15)+1,"##")&"]") -> [UC06-6] | B16: Nhập đầy đủ các textbox | C16: - Truy cập vào hệ thống http://34.143.239.189/ - Bài tuyển dụng đã được tạo | D16: 1. Vào trang Tạo thông tin tuyển dụng 2. Click vào button cây viết ở bài đăng 3. Nhập đầy đủ thông các textbox 4. Click vào button Chỉnh sửa | E16: - Chỉnh sửa thành công và hiển thị thông báo “Sửa thông tin thành công” | F16: Fail | H16: =B3 -> Việt | I16: Một số field sau khi chỉnh sửa không được lưu EV: https://drive.google.com/file/d/18mGEMclO5z7i1m1icszJX2MbDYCM2Mqd/view?usp=drive_link
B17: 1.3. Kiểm tra chức năng Xóa bài đăng
A18: =IF(AND(E18=""),"","["&TEXT($B$1,"##")&"-"&TEXT(ROW()-9-COUNTBLANK($E$8:E17)+1,"##")&"]") -> [UC06-7] | B18: Kiểm tra chức năng xóa bài đăng | C18: - Truy cập vào hệ thống http://34.143.239.189/ - Bài tuyển dụng đã được tạo | D18: 1. Vào trang Tạo thông tin tuyển dụng 2. Click vào button xóa ở bài đăng | E18: Xóa thành công và hiển thị thông báo “Tin đã được xóa thành công” | F18: Fail | H18: =B3 -> Việt | I18: Sau khi xóa, bài đăng ko mất ngay mà phải reload lại trang EV:https://drive.google.com/file/d/1PNc_J1T9vs7rbCIJVUC5t629eFX_cgui/view?usp=drive_link

Sheet Đăng nhập hệ thống
A1: Item Test | B1: UC03
A2: Test requirement | B2: Ensure that all features listed below work properly without any errors when using the below browsers. - Edge in latest version - Google Chrome in latest version
A3: Tester | B3: Việt
A4: Pass | B4: Fail | C4: NT | D4: N/A | E4: Number of Test cases
A5: =COUNTIF(F:F,"Pass") -> 14 | B5: =COUNTIF(F:F,"Fail") -> 13 | C5: =COUNTIF(F:F,"Untested") -> 7 | D5: =COUNTIF(F:F,"N/A") -> 6 | E5: =SUM(A5:D5) -> 40
A6: % | B6: % | C6: % | D6: %
A8: ID | B8: Test Case Description | C8: Pre-condition | D8: Test Case Procedure | E8: Expected Output | F8: Result | G8: Test date | H8: Tester | I8: Note
B9: 1.1. Kiểm tra giao diện
A10: =IF(AND(E10=""),"","["&TEXT($B$1,"##")&"-"&TEXT(ROW()-9-COUNTBLANK($E$8:E9)+1,"##")&"]") -> [UC03-1] | B10: Kiểm tra tổng quan màn hình Đăng nhập | C10: - Truy cập vào hệ thống http://34.143.239.189/ - User đã đăng ký tài khoản | D10: 1. Vào trang đăng nhập và đăng ký. | E10: Màn hình hiển thị đầy đủ các field gồm: - Ứng viên: + Button: Đăng ký ứng viên, Đăng nhập + Icon: Tài khoản, mật khẩu + Textbox: Tài khoản, mật khẩu - Nhà tuyển dụng: + Button: Đăng ký ứng viên, Đăng nhập + Icon: Tài khoản, mật khẩu + Textbox: Tài khoản, mật khẩu - Nhà quản trị: + Button: Đăng ký ứng viên, Đăng nhập + Icon: Tài khoản, mật khẩu + Textbox: Tài khoản, mật khẩu | F10: Pass | G10: 20/04/2024 | H10: =B3 -> Việt
A11: =IF(AND(E11=""),"","["&TEXT($B$1,"##")&"-"&TEXT(ROW()-9-COUNTBLANK($E$8:E10)+1,"##")&"]") -> [UC03-2] | B11: Kiểm tra chi tiết các button của Ứng viên | C11: - Truy cập vào hệ thống http://34.143.239.189/ - User đã đăng ký tài khoản | D11: 1. Vào trang đăng nhập và đăng ký. | E11: Cho phép click vào các button | F11: Pass | G11: 20/04/2024 | H11: =B3 -> Việt
A12: =IF(AND(E12=""),"","["&TEXT($B$1,"##")&"-"&TEXT(ROW()-9-COUNTBLANK($E$8:E11)+1,"##")&"]") -> [UC03-3] | B12: Kiểm tra chi tiết các textbox của Ứng viên | C12: - Truy cập vào hệ thống http://34.143.239.189/ - User đã đăng ký tài khoản | D12: 1. Vào trang đăng nhập và đăng ký. | E12: - Watermark ứng với các field - Cho phép nhập thông tin vào field | F12: Pass | G12: 20/04/2024 | H12: =B3 -> Việt
A13: =IF(AND(E13=""),"","["&TEXT($B$1,"##")&"-"&TEXT(ROW()-9-COUNTBLANK($E$8:E12)+1,"##")&"]") -> [UC03-4] | B13: Kiểm tra các Icon của Ứng viên | C13: - Truy cập vào hệ thống http://34.143.239.189/ - User đã đăng ký tài khoản | D13: 1. Vào trang đăng nhập và đăng ký. | E13: Các icon ứng với các field ở màn hình theo yêu cầu | F13: Pass | G13: 20/04/2024 | H13: =B3 -> Việt
A14: =IF(AND(E14=""),"","["&TEXT($B$1,"##")&"-"&TEXT(ROW()-9-COUNTBLANK($E$8:E13)+1,"##")&"]") -> [UC03-5] | B14: Kiểm tra chi tiết các button của Nhà tuyển dụng | C14: - Truy cập vào hệ thống http://34.143.239.189/ - User đã đăng ký tài khoản | D14: 1. Vào trang đăng nhập và đăng ký. | E14: Cho phép click vào các button | F14: Pass | G14: 20/04/2024 | H14: =B3 -> Việt
A15: =IF(AND(E15=""),"","["&TEXT($B$1,"##")&"-"&TEXT(ROW()-9-COUNTBLANK($E$8:E14)+1,"##")&"]") -> [UC03-6] | B15: Kiểm tra chi tiết các textbox của Nhà tuyển dụng | C15: - Truy cập vào hệ thống http://34.143.239.189/ - User đã đăng ký tài khoản | D15: 1. Vào trang đăng nhập và đăng ký. | E15: - Watermark ứng với các field - Cho phép nhập thông tin vào field | F15: Pass | G15: 20/04/2024 | H15: =B3 -> Việt
A16: =IF(AND(E16=""),"","["&TEXT($B$1,"##")&"-"&TEXT(ROW()-9-COUNTBLANK($E$8:E15)+1,"##")&"]") -> [UC03-7] | B16: Kiểm tra các Icon của Nhà tuyển dụng | C16: - Truy cập vào hệ thống http://34.143.239.189/ - User đã đăng ký tài khoản | D16: 1. Vào trang đăng nhập và đăng ký. | E16: Các icon ứng với các field ở màn hình theo yêu cầu | F16: Pass | G16: 20/04/2024 | H16: =B3 -> Việt
A17: =IF(AND(E17=""),"","["&TEXT($B$1,"##")&"-"&TEXT(ROW()-9-COUNTBLANK($E$8:E16)+1,"##")&"]") -> [UC03-8] | B17: Kiểm tra chi tiết các button của Nhà quản trị | C17: - Truy cập vào hệ thống http://34.143.239.189/ - User đã đăng ký tài khoản | D17: 1. Vào trang đăng nhập và đăng ký. | E17: Cho phép click vào các button | F17: N/A | H17: =B3 -> Việt | I17: Chưa có màn hình
A18: =IF(AND(E18=""),"","["&TEXT($B$1,"##")&"-"&TEXT(ROW()-9-COUNTBLANK($E$8:E17)+1,"##")&"]") -> [UC03-9] | B18: Kiểm tra chi tiết các textbox của Nhà quản trị | C18: - Truy cập vào hệ thống http://34.143.239.189/ - User đã đăng ký tài khoản | D18: 1. Vào trang đăng nhập và đăng ký. | E18: - Watermark ứng với các field - Cho phép nhập thông tin vào field | F18: N/A | H18: =B3 -> Việt | I18: Chưa có màn hình
A19: =IF(AND(E19=""),"","["&TEXT($B$1,"##")&"-"&TEXT(ROW()-9-COUNTBLANK($E$8:E18)+1,"##")&"]") -> [UC03-10] | B19: Kiểm tra các Icon của Nhà quản trị | C19: - Truy cập vào hệ thống http://34.143.239.189/ - User đã đăng ký tài khoản | D19: 1. Vào trang đăng nhập và đăng ký. | E19: Các icon ứng với các field ở màn hình theo yêu cầu | F19: N/A | H19: =B3 -> Việt | I19: Chưa có màn hình
B20: 1.2. Kiểm tra chức năng Đăng nhập ứng viên
A21: =IF(AND(E21=""),"","["&TEXT($B$1,"##")&"-"&TEXT(ROW()-9-COUNTBLANK($E$8:E20)+1,"##")&"]") -> [UC03-11] | B21: Bỏ trống Tài khoản | C21: - Truy cập vào hệ thống http://34.143.239.189/ - User đã đăng ký tài khoản | D21: 1. Vào trang đăng nhập và đăng ký. 2. Nhập Password và bỏ trống Tài khoản cho ứng viên 3. Bấm nút Đăng nhập | E21: Đăng nhập thất bại và hiển thị thông báo “Tài khoản hoặc mật khẩu không hợp lệ” | F21: Pass | G21: 20/04/2024 | H21: =B3 -> Việt
A22: =IF(AND(E22=""),"","["&TEXT($B$1,"##")&"-"&TEXT(ROW()-9-COUNTBLANK($E$8:E21)+1,"##")&"]") -> [UC03-12] | B22: Nhập tài khoản không tồn tại | C22: - Truy cập vào hệ thống http://34.143.239.189/ | D22: 1. Vào trang đăng nhập và đăng ký. 2. Nhập tài khoản chưa từng được đăng ký và Password 3. Bấm nút Đăng nhập | E22: Đăng nhập thất bại và hiển thị thông báo “Tài khoản không tồn tại” | F22: Pass | G22: 20/04/2024 | H22: =B3 -> Việt
A23: =IF(AND(E23=""),"","["&TEXT($B$1,"##")&"-"&TEXT(ROW()-9-COUNTBLANK($E$8:E22)+1,"##")&"]") -> [UC03-13] | B23: Bỏ trống password | C23: - Truy cập vào hệ thống http://34.143.239.189/ - User đã đăng ký tài khoản | D23: 1. Vào trang đăng nhập và đăng ký. 2. Nhập đúng tài khoản và bỏ trống password 3. Bấm nút Đăng nhập | E23: Đăng nhập thất bại và hiển thị thông báo “Tài khoản hoặc mật khẩu không hợp lệ” | F23: Fail | G23: 20/04/2024 | H23: =B3 -> Việt | I23: Đang cho phép đăng nhập khi bỏ trống mật khẩu EV: https://drive.google.com/file/d/19ypJ2tZzglZAPtMBmcVJD0675kWaUYrZ/view?usp=drive_link
A24: =IF(AND(E24=""),"","["&TEXT($B$1,"##")&"-"&TEXT(ROW()-9-COUNTBLANK($E$8:E23)+1,"##")&"]") -> [UC03-14] | B24: Nhập sai định dạng password | C24: - Truy cập vào hệ thống http://34.143.239.189/ - User đã đăng ký tài khoản | D24: 1. Vào trang đăng nhập và đăng ký. 2. Nhập đúng tài khoản 3. Nhập password ít hơn 8 ký tự 4. Bấm nút Đăng nhập | E24: Đăng nhập không thành công và hiển thị thông báo “Mật khẩu không hợp lệ, mật khẩu phải tối thiểu 8 kí tự, bao gồm chữ hoa, thường, số và kí tự đặc biệt” | F24: Fail | G24: 20/04/2024 | H24: =B3 -> Việt | I24: Đang cho phép đăng nhập vào hệ thống EV: https://drive.google.com/file/d/1h-wCW7b78BLiKHfnXgaUNKW_PRXHmjf0/view?usp=drive_link
A25: =IF(AND(E25=""),"","["&TEXT($B$1,"##")&"-"&TEXT(ROW()-9-COUNTBLANK($E$8:E24)+1,"##")&"]") -> [UC03-15] | C25: - Truy cập vào hệ thống http://34.143.239.189/ - User đã đăng ký tài khoản | D25: 1. Vào trang đăng nhập và đăng ký. 2. Nhập đúng tài khoản 3. Nhập password thiếu chữ hoa nhưng >= 8 ký tự, chữ thường, số và kí tự đặc biệt 4. Bấm nút Đăng nhập | E25: Đăng nhập không thành công và hiển thị thông báo “Mật khẩu không hợp lệ, mật khẩu phải tối thiểu 8 kí tự, bao gồm chữ hoa, thường, số và kí tự đặc biệt” | F25: Fail | G25: 20/04/2024 | H25: =B3 -> Việt | I25: Đang cho phép đăng nhập vào hệ thống EV: https://drive.google.com/file/d/1swAQuKDkMv5N6JiBh9XJ0T3Uxminz4RR/view?usp=drive_link
A26: =IF(AND(E26=""),"","["&TEXT($B$1,"##")&"-"&TEXT(ROW()-9-COUNTBLANK($E$8:E25)+1,"##")&"]") -> [UC03-16] | C26: - Truy cập vào hệ thống http://34.143.239.189/ - User đã đăng ký tài khoản | D26: 1. Vào trang đăng nhập và đăng ký. 2. Nhập đúng tài khoản 3. Nhập password thiếu chữ thường nhưng >= 8 ký tự, chữ hoa, số và kí tự đặc biệt 4. Bấm nút Đăng nhập | E26: Đăng nhập không thành công và hiển thị thông báo “Mật khẩu không hợp lệ, mật khẩu phải tối thiểu 8 kí tự, bao gồm chữ hoa, thường, số và kí tự đặc biệt” | F26: Fail | G26: 20/04/2024 | H26: =B3 -> Việt | I26: Đang cho phép đăng nhập vào hệ thống EV: https://drive.google.com/file/d/1DRp5BszKpyEBFZi4GQfhb5Qxt_ohn63U/view?usp=drive_link
A27: =IF(AND(E27=""),"","["&TEXT($B$1,"##")&"-"&TEXT(ROW()-9-COUNTBLANK($E$8:E26)+1,"##")&"]") -> [UC03-17] | C27: - Truy cập vào hệ thống http://34.143.239.189/ - User đã đăng ký tài khoản | D27: 1. Vào trang đăng nhập và đăng ký. 2. Nhập đúng tài khoản 3. Nhập password thiếu số nhưng >= 8 ký tự, chữ hoa, chữ thường và kí tự đặc biệt 4. Bấm nút Đăng nhập | E27: Đăng nhập không thành công và hiển thị thông báo “Mật khẩu không hợp lệ, mật khẩu phải tối thiểu 8 kí tự, bao gồm chữ hoa, thường, số và kí tự đặc biệt” | F27: Fail | G27: 20/04/2024 | H27: =B3 -> Việt | I27: Đang cho phép đăng nhập vào hệ thống EV: https://drive.google.com/file/d/1hUV0ykvJY_Ltk4SsSZWumT7qPed3M1va/view?usp=drive_link
A28: =IF(AND(E28=""),"","["&TEXT($B$1,"##")&"-"&TEXT(ROW()-9-COUNTBLANK($E$8:E27)+1,"##")&"]") -> [UC03-18] | C28: - Truy cập vào hệ thống http://34.143.239.189/ - User đã đăng ký tài khoản | D28: 1. Vào trang đăng nhập và đăng ký. 2. Nhập đúng tài khoản 3. Nhập password thiếu kí tự đặc biệt nhưng >= 8 ký tự, chữ hoa, chữ thường và số 4. Bấm nút Đăng nhập | E28: Đăng nhập không thành công và hiển thị thông báo “Mật khẩu không hợp lệ, mật khẩu phải tối thiểu 8 kí tự, bao gồm chữ hoa, thường, số và kí tự đặc biệt” | F28: Fail | G28: 20/04/2024 | H28: =B3 -> Việt | I28: Đang cho phép đăng nhập vào hệ thống EV: https://drive.google.com/file/d/1QtpnfPR_U_l5AIsQK0n_7BCBgucGM7QZ/view?usp=drive_link
A29: =IF(AND(E29=""),"","["&TEXT($B$1,"##")&"-"&TEXT(ROW()-9-COUNTBLANK($E$8:E28)+1,"##")&"]") -> [UC03-19] | B29: Nhập sai password | C29: - Truy cập vào hệ thống http://34.143.239.189/ - User đã đăng ký tài khoản | D29: 1. Vào trang đăng nhập và đăng ký. 2. Nhập đúng tài khoản 3. Nhập sai password 4. Bấm nút Đăng nhập | E29: Đăng nhập không thành công và hiển thị thông báo “Đăng nhập thành công” | F29: Fail | G29: 20/04/2024 | H29: =B3 -> Việt | I29: Đang cho phép đăng nhập EV: https://drive.google.com/file/d/1rw38kN3U6ys8Kj-siYZ_zxF0pu1UGTy1/view?usp=drive_link
A30: =IF(AND(E30=""),"","["&TEXT($B$1,"##")&"-"&TEXT(ROW()-9-COUNTBLANK($E$8:E29)+1,"##")&"]") -> [UC03-20] | B30: Nhập đúng Tài khoản và Password | C30: - Truy cập vào hệ thống http://34.143.239.189/ - User đã đăng ký tài khoản | D30: 1. Vào trang đăng nhập và đăng ký. 2. Nhập đúng tài khoản và password 3. Bấm nút Đăng nhập | E30: Hiện popup thông báo đăng nhập thành công | F30: Pass | G30: 20/04/2024 | H30: =B3 -> Việt
B31: 1.3. Kiểm tra chức năng Đăng nhập Nhà tuyển dụng
A32: =IF(AND(E32=""),"","["&TEXT($B$1,"##")&"-"&TEXT(ROW()-9-COUNTBLANK($E$8:E31)+1,"##")&"]") -> [UC03-21] | B32: Bỏ trống Tài khoản | C32: - Truy cập vào hệ thống http://34.143.239.189/ - User đã đăng ký tài khoản | D32: 1. Vào trang đăng nhập và đăng ký. 2. Nhập Password và bỏ trống Tài khoản cho Nhà tuyển dụng 3. Bấm nút Đăng nhập | E32: Đăng nhập thất bại và hiển thị thông báo “Tài khoản hoặc mật khẩu không hợp lệ” | F32: Pass | G32: 20/04/2024 | H32: =B3 -> Việt
A33: =IF(AND(E33=""),"","["&TEXT($B$1,"##")&"-"&TEXT(ROW()-9-COUNTBLANK($E$8:E32)+1,"##")&"]") -> [UC03-22] | B33: Nhập tài khoản không tồn tại | C33: - Truy cập vào hệ thống http://34.143.239.189/ | D33: 1. Vào trang đăng nhập và đăng ký. 2. Nhập tài khoản chưa từng được đăng ký và Password 3. Bấm nút Đăng nhập | E33: Đăng nhập thất bại và hiển thị thông báo “Tài khoản không tồn tại” | F33: Pass | G33: 20/04/2024 | H33: =B3 -> Việt
A34: =IF(AND(E34=""),"","["&TEXT($B$1,"##")&"-"&TEXT(ROW()-9-COUNTBLANK($E$8:E33)+1,"##")&"]") -> [UC03-23] | B34: Bỏ trống password | C34: - Truy cập vào hệ thống http://34.143.239.189/ - User đã đăng ký tài khoản | D34: 1. Vào trang đăng nhập và đăng ký. 2. Nhập đúng tài khoản và bỏ trống password 3. Bấm nút Đăng nhập | E34: Đăng nhập thất bại và hiển thị thông báo “Tài khoản hoặc mật khẩu không hợp lệ” | F34: Pass | G34: 20/04/2024 | H34: =B3 -> Việt
A35: =IF(AND(E35=""),"","["&TEXT($B$1,"##")&"-"&TEXT(ROW()-9-COUNTBLANK($E$8:E34)+1,"##")&"]") -> [UC03-24] | B35: Nhập sai định dạng password | C35: - Truy cập vào hệ thống http://34.143.239.189/ - User đã đăng ký tài khoản | D35: 1. Vào trang đăng nhập và đăng ký. 2. Nhập đúng tài khoản 3. Nhập password ít hơn 8 ký tự 4. Bấm nút Đăng nhập | E35: Đăng nhập không thành công và hiển thị thông báo “Mật khẩu không hợp lệ, mật khẩu phải tối thiểu 8 kí tự, bao gồm chữ hoa, thường, số và kí tự đặc biệt” | F35: Fail | G35: 20/04/2024 | H35: =B3 -> Việt | I35: Đang cho phép đăng nhập EV: https://drive.google.com/file/d/13EfGpvy6sct5B6tOmA7_dY26448o0_40/view?usp=drive_link
A36: =IF(AND(E36=""),"","["&TEXT($B$1,"##")&"-"&TEXT(ROW()-9-COUNTBLANK($E$8:E35)+1,"##")&"]") -> [UC03-25] | C36: - Truy cập vào hệ thống http://34.143.239.189/ - User đã đăng ký tài khoản | D36: 1. Vào trang đăng nhập và đăng ký. 2. Nhập đúng tài khoản 3. Nhập password thiếu chữ hoa nhưng >= 8 ký tự, chữ thường, số và kí tự đặc biệt 4. Bấm nút Đăng nhập | E36: Đăng nhập không thành công và hiển thị thông báo “Mật khẩu không hợp lệ, mật khẩu phải tối thiểu 8 kí tự, bao gồm chữ hoa, thường, số và kí tự đặc biệt” | F36: Fail | G36: 20/04/2024 | H36: =B3 -> Việt | I36: Đang cho phép đăng nhập EV: https://drive.google.com/file/d/1GqX_-F-Q9K4TufDjRqYLcsWi65Uhd1eV/view?usp=drive_link
A37: =IF(AND(E37=""),"","["&TEXT($B$1,"##")&"-"&TEXT(ROW()-9-COUNTBLANK($E$8:E36)+1,"##")&"]") -> [UC03-26] | C37: - Truy cập vào hệ thống http://34.143.239.189/ - User đã đăng ký tài khoản | D37: 1. Vào trang đăng nhập và đăng ký. 2. Nhập đúng tài khoản 3. Nhập password thiếu chữ thường nhưng >= 8 ký tự, chữ hoa, số và kí tự đặc biệt 4. Bấm nút Đăng nhập | E37: Đăng nhập không thành công và hiển thị thông báo “Mật khẩu không hợp lệ, mật khẩu phải tối thiểu 8 kí tự, bao gồm chữ hoa, thường, số và kí tự đặc biệt” | F37: Fail | G37: 20/04/2024 | H37: =B3 -> Việt | I37: Đang cho phép đăng nhập EV:https://drive.google.com/file/d/1dEkF2PndAFKi-4EVolThPXzvj6yVHl6M/view?usp=drive_link
A38: =IF(AND(E38=""),"","["&TEXT($B$1,"##")&"-"&TEXT(ROW()-9-COUNTBLANK($E$8:E37)+1,"##")&"]") -> [UC03-27] | C38: - Truy cập vào hệ thống http://34.143.239.189/ - User đã đăng ký tài khoản | D38: 1. Vào trang đăng nhập và đăng ký. 2. Nhập đúng tài khoản 3. Nhập password thiếu số nhưng >= 8 ký tự, chữ hoa, chữ thường và kí tự đặc biệt 4. Bấm nút Đăng nhập | E38: Đăng nhập không thành công và hiển thị thông báo “Mật khẩu không hợp lệ, mật khẩu phải tối thiểu 8 kí tự, bao gồm chữ hoa, thường, số và kí tự đặc biệt” | F38: Fail | G38: 20/04/2024 | H38: =B3 -> Việt | I38: Đang cho phép đăng nhập EV: https://drive.google.com/file/d/12Yi8UNrZW-wERJuGWXxib86NNIGf7a-O/view?usp=drive_link
A39: =IF(AND(E39=""),"","["&TEXT($B$1,"##")&"-"&TEXT(ROW()-9-COUNTBLANK($E$8:E38)+1,"##")&"]") -> [UC03-28] | C39: - Truy cập vào hệ thống http://34.143.239.189/ - User đã đăng ký tài khoản | D39: 1. Vào trang đăng nhập và đăng ký. 2. Nhập đúng tài khoản 3. Nhập password thiếu kí tự đặc biệt nhưng >= 8 ký tự, chữ hoa, chữ thường và số 4. Bấm nút Đăng nhập | E39: Đăng nhập không thành công và hiển thị thông báo “Mật khẩu không hợp lệ, mật khẩu phải tối thiểu 8 kí tự, bao gồm chữ hoa, thường, số và kí tự đặc biệt” | F39: Fail | G39: 20/04/2024 | H39: =B3 -> Việt | I39: Đang cho phép đăng nhập EV: https://drive.google.com/file/d/1xChYkdv1fXz-LQ_K-a4ezgSb4sbHzZnM/view?usp=drive_link
A40: =IF(AND(E40=""),"","["&TEXT($B$1,"##")&"-"&TEXT(ROW()-9-COUNTBLANK($E$8:E39)+1,"##")&"]") -> [UC03-29] | B40: Nhập sai password | C40: - Truy cập vào hệ thống http://34.143.239.189/ - User đã đăng ký tài khoản | D40: 1. Vào trang đăng nhập và đăng ký. 2. Nhập đúng tài khoản 3. Nhập sai password 4. Bấm nút Đăng nhập | E40: Đăng nhập không thành công và hiển thị thông báo “Đăng nhập không thành công” | F40: Fail | G40: 20/04/2024 | H40: =B3 -> Việt | I40: Đang cho phép đăng nhập EV: https://drive.google.com/file/d/1Hbvgn6jyb-uRBEPcOnjTyTqu-D10ppyC/view?usp=drive_link
A41: =IF(AND(E41=""),"","["&TEXT($B$1,"##")&"-"&TEXT(ROW()-9-COUNTBLANK($E$8:E40)+1,"##")&"]") -> [UC03-30] | B41: Nhập đúng Tài khoản và Password | C41: - Truy cập vào hệ thống http://34.143.239.189/ - User đã đăng ký tài khoản | D41: 1. Vào trang đăng nhập và đăng ký. 2. Nhập đúng tài khoản và password 3. Bấm nút Đăng nhập | E41: Hiện popup thông báo đăng nhập thành công | F41: Pass | H41: =B3 -> Việt
...

Sheet Đăng xuất tài khoản
A1: Item Test | B1: UC04
A2: Test requirement | B2: Ensure that all features listed below work properly without any errors when using the below browsers. - Edge in latest version - Google Chrome in latest version
A3: Tester | B3: Việt
A4: Pass | B4: Fail | C4: NT | D4: N/A | E4: Number of Test cases
A5: =COUNTIF(F:F,"Pass") -> 2 | B5: =COUNTIF(F:F,"Fail") -> 0 | C5: =COUNTIF(F:F,"Untested") -> 0 | D5: =COUNTIF(F:F,"N/A") -> 1 | E5: =SUM(A5:D5) -> 3
A6: % | B6: % | C6: % | D6: %
A8: ID | B8: Test Case Description | C8: Pre-condition | D8: Test Case Procedure | E8: Expected Output | F8: Result | G8: Test date | H8: Tester | I8: Note
B9: 1.1. Kiểm tra giao diện
B10: 1.2. Kiểm tra chức năng Đăng xuất Ứng viên
A11: =IF(AND(E11=""),"","["&TEXT($B$1,"##")&"-"&TEXT(ROW()-9-COUNTBLANK($E$8:E10)+1,"##")&"]") -> [UC04-1] | B11: Kiểm tra chức năng đăng xuất | C11: - Truy cập vào hệ thống http://34.143.239.189/ - User đăng nhập vào hê thống | D11: 1. Đăng nhập vào hệ thống 2. Đăng xuất tài khoản | E11: Quay lại màn hình đăng nhập và đăng ký | F11: Pass | G11: 20/04/2024 | H11: =B3 -> Việt
B12: 1.2. Kiểm tra chức năng Đăng xuất Nhà tuyển dụng
A13: =IF(AND(E13=""),"","["&TEXT($B$1,"##")&"-"&TEXT(ROW()-9-COUNTBLANK($E$8:E12)+1,"##")&"]") -> [UC04-2] | B13: Kiểm tra chức năng đăng xuất | C13: - Truy cập vào hệ thống http://34.143.239.189/ - User đăng nhập vào hê thống | D13: 1. Đăng nhập vào hệ thống 2. Đăng xuất tài khoản | E13: Quay lại màn hình đăng nhập và đăng ký | F13: Pass | G13: 20/04/2024 | H13: =B3 -> Việt
B14: 1.2. Kiểm tra chức năng Đăng xuất Nhà quản trị
A15: =IF(AND(E15=""),"","["&TEXT($B$1,"##")&"-"&TEXT(ROW()-9-COUNTBLANK($E$8:E14)+1,"##")&"]") -> [UC04-3] | B15: Kiểm tra chức năng đăng xuất | C15: - Truy cập vào hệ thống http://34.143.239.189/ - User đăng nhập vào hê thống | D15: 1. Đăng nhập vào hệ thống 2. Đăng xuất tài khoản | E15: Quay lại màn hình đăng nhập và đăng ký | F15: N/A | H15: =B3 -> Việt | I15: Không có màn hình

Sheet Đăng bài tìm ứng viên
A1: Item Test | B1: UC05
A2: Test requirement | B2: Ensure that all features listed below work properly without any errors when using the below browsers. - Edge in latest version - Google Chrome in latest version
A3: Tester | B3: Việt
A4: Pass | B4: Fail | C4: NT | D4: N/A | E4: Number of Test cases
A5: =COUNTIF(F:F,"Pass") -> 6 | B5: =COUNTIF(F:F,"Fail") -> 1 | C5: =COUNTIF(F:F,"Untested") -> 0 | D5: =COUNTIF(F:F,"N/A") -> 0 | E5: =SUM(A5:D5) -> 7
A6: % | B6: % | C6: % | D6: %
A8: ID | B8: Test Case Description | C8: Pre-condition | D8: Test Case Procedure | E8: Expected Output | F8: Result | G8: Test date | H8: Tester | I8: Note
B9: 1.1. Kiểm tra giao diện
A10: =IF(AND(E10=""),"","["&TEXT($B$1,"##")&"-"&TEXT(ROW()-9-COUNTBLANK($E$8:E9)+1,"##")&"]") -> [UC05-1] | B10: Kiểm tra tổng quan màn hình Đăng thông tin tuyển dụng | C10: - Truy cập vào hệ thống http://34.143.239.189/ - User đã đăng ký tài khoản | D10: 1. Vào trang Tạo thông tin tuyển dụng | E10: Màn hình hiển thị đầy đủ các field gồm: - Textbox: Tên công việc, Kinh nghiệm, Học vấn, Địa chỉ, Mô tả công việc, Yêu cầu, Lương, Trình độ - Button: Tạo | F10: Pass | G10: 20/04/2024 | H10: =B3 -> Việt
A11: =IF(AND(E11=""),"","["&TEXT($B$1,"##")&"-"&TEXT(ROW()-9-COUNTBLANK($E$8:E10)+1,"##")&"]") -> [UC05-2] | B11: Kiểm tra chi tiết các textbox | C11: - Truy cập vào hệ thống http://34.143.239.189/ - User đã đăng ký tài khoản | D11: 1. Vào trang Tạo thông tin tuyển dụng 2. Nhập thông tin vào các textbox | E11: - Cho phép nhập thông tin vào các textbox - Mặc định watermark ứng với các field | F11: Pass | G11: 20/04/2024 | H11: =B3 -> Việt
A12: =IF(AND(E12=""),"","["&TEXT($B$1,"##")&"-"&TEXT(ROW()-9-COUNTBLANK($E$8:E11)+1,"##")&"]") -> [UC05-3] | B12: Kiểm tra textbox mức lương | C12: - Truy cập vào hệ thống http://34.143.239.189/ - User đã đăng ký tài khoản | D12: 1. Vào trang Tạo thông tin tuyển dụng 2. Nhập thông tin vào textbox mức lương | E12: Cho phép nhập kiểu dữ liệu số | F12: Pass | G12: 20/04/2024 | H12: =B3 -> Việt
A13: =IF(AND(E13=""),"","["&TEXT($B$1,"##")&"-"&TEXT(ROW()-9-COUNTBLANK($E$8:E11)+1,"##")&"]") -> [UC05-4] | B13: Kiểm tra chi tiết button Tạo | C13: - Truy cập vào hệ thống http://34.143.239.189/ - User đã đăng ký tài khoản | D13: 1. Vào trang Tạo thông tin tuyển dụng 2. Click vào button | E13: Cho phép click vào button | F13: Pass | G13: 20/04/2024 | H13: =B3 -> Việt
B14: 1.2. Kiểm tra chức năng Tạo thông tin tuyển dụng
A15: =IF(AND(E15=""),"","["&TEXT($B$1,"##")&"-"&TEXT(ROW()-9-COUNTBLANK($E$8:E14)+1,"##")&"]") -> [UC05-5] | B15: Bỏ trống các trường bắt buộc | C15: - Truy cập vào hệ thống http://34.143.239.189/ - User đã đăng ký tài khoản | D15: 1. Vào trang Tạo thông tin tuyển dụng 2. Nhập thông tin vào các textbox nhưng bỏ trống các trường bắt buộc gồm (tên công việc, mô tả công việc, yêu cầu, mức lương, địa chỉ) 3. Bấm Tạo | E15: Tạo công việc thấ bại và hiển thị thông báo “Có thể bạn nhập chưa đầy đủ hoặc sai thông tin” | F15: Pass | G15: 20/04/2024 | H15: =B3 -> Việt
A16: =IF(AND(E16=""),"","["&TEXT($B$1,"##")&"-"&TEXT(ROW()-9-COUNTBLANK($E$8:E15)+1,"##")&"]") -> [UC05-6] | B16: Bỏ trống các field không bắt buộc | C16: - Truy cập vào hệ thống http://34.143.239.189/ | D16: 1. Vào trang Tạo thông tin tuyển dụng 2. Nhập thông tin vào các textbox bắt buộc gồm (tên công việc, mô tả công việc, yêu cầu, mức lương, địa chỉ) và bỏ trống các field còn lại 3. Bấm Tạo | E16: - Đăng bài thành công và hiển thị thông báo “Tạo công việc thành công” - Hệ thống chuyển về trang chủ, hiển thị tin lên đầu danh sách là tin mới nhất | F16: Fail | G16: 20/04/2024 | H16: =B3 -> Việt | I16: Các field không bắt buộc nhưng lại bắt buộc nhập EV: https://drive.google.com/file/d/1YoY9AIFcMT52uaFrtkkwH34edDRbwDtv/view?usp=drive_link
A17: =IF(AND(E17=""),"","["&TEXT($B$1,"##")&"-"&TEXT(ROW()-9-COUNTBLANK($E$8:E16)+1,"##")&"]") -> [UC05-7] | B17: Nhập đầy đủ các textbox | C17: - Truy cập vào hệ thống http://34.143.239.189/ - User đã đăng ký tài khoản | D17: 1. Vào trang Tạo thông tin tuyển dụng 2. Nhập thông tin ở tất cả các texbox 3. Bấm Tạo | E17: - Đăng bài thành công và hiển thị thông báo “Tạo công việc thành công” - Hệ thống chuyển về trang chủ, hiển thị tin lên đầu danh sách là tin mới nhất | F17: Pass | H17: =B3 -> Việt

Sheet Xem ứng viên ứng tuyển
A1: Item Test | B1: UC07
A2: Test requirement | B2: Ensure that all features listed below work properly without any errors when using the below browsers. - Edge in latest version - Google Chrome in latest version
A3: Tester | B3: Việt
A4: Pass | B4: Fail | C4: NT | D4: N/A | E4: Number of Test cases
A5: =COUNTIF(F:F,"Pass") -> 1 | B5: =COUNTIF(F:F,"Fail") -> 1 | C5: =COUNTIF(F:F,"Untested") -> 0 | D5: =COUNTIF(F:F,"N/A") -> 0 | E5: =SUM(A5:D5) -> 2
A6: % | B6: % | C6: % | D6: %
A8: ID | B8: Test Case Description | C8: Pre-condition | D8: Test Case Procedure | E8: Expected Output | F8: Result | G8: Test date | H8: Tester | I8: Note
B9: 1.1. Kiểm tra giao diện
A10: =IF(AND(E10=""),"","["&TEXT($B$1,"##")&"-"&TEXT(ROW()-9-COUNTBLANK($E$8:E9)+1,"##")&"]") -> [UC07-1] | B10: Kiểm tra tổng quan giao diện xem ứng viên | C10: - Truy cập vào hệ thống http://34.143.239.189/ | D10: 1. Nhà tuyển dụng vào trang nhà tuyển dụng. 2. Vào mục xem ứng viên | E10: Hệ thống hiển thị danh sách ứng viên đã ứng tuyển | F10: Pass | G10: 21/04/2024 | H10: =B3 -> Việt
B11: 1.2. Kiểm tra chức năng
A12: =IF(AND(E12=""),"","["&TEXT($B$1,"##")&"-"&TEXT(ROW()-9-COUNTBLANK($E$8:E11)+1,"##")&"]") -> [UC07-2] | B12: Kiểm tra chức năng xem chi tiết ứng viên | C12: - Truy cập vào hệ thống http://34.143.239.189/ | D12: 1. Nhà tuyển dụng vào trang nhà tuyển dụng. 2. Vào mục xem ứng viên 3. Click vào button Xem chi tiết ứng viên | E12: Hệ thống chuyển đến trang chi tiết hồ sơ của ứng viên. | F12: Fail | G12: 21/04/2024 | H12: =B3 -> Việt | I12: Không thể click vào button xem hồ sơ ứng viên EV: https://drive.google.com/file/d/1dE5MnOrfdkUWOn0plfCUkZlO94rTgwKc/view?usp=drive_link

Sheet Ứng tuyển công việc
A1: Item Test | B1: UC08
A2: Test requirement | B2: Ensure that all features listed below work properly without any errors when using the below browsers. - Edge in latest version - Google Chrome in latest version
A3: Tester | B3: Việt
A4: Pass | B4: Fail | C4: NT | D4: N/A | E4: Number of Test cases
A5: =COUNTIF(F:F,"Pass") -> 2 | B5: =COUNTIF(F:F,"Fail") -> 3 | C5: =COUNTIF(F:F,"Untested") -> 0 | D5: =COUNTIF(F:F,"N/A") -> 1 | E5: =SUM(A5:D5) -> 6
A6: % | B6: % | C6: % | D6: %
A8: ID | B8: Test Case Description | C8: Pre-condition | D8: Test Case Procedure | E8: Expected Output | F8: Result | G8: Test date | H8: Tester | I8: Note
B9: 1.1. Kiểm tra giao diện
A10: =IF(AND(E10=""),"","["&TEXT($B$1,"##")&"-"&TEXT(ROW()-9-COUNTBLANK($E$8:E9)+1,"##")&"]") -> [UC08-1] | B10: Kiểm tra tổng quan giao diện ứng tuyển công việc | C10: - Truy cập vào hệ thống http://34.143.239.189/ | D10: 1. Ứng viên vào mục "Tìm việc" | E10: Hệ thống hiển thị đầy đủ các trường gồm: - Tìm kiếm theo tên nhà tuyển dụng - Tìm kiếm theo lĩnh vực - Lọc theo thời hạn nộp hồ sơ - Tìm kiếm theo vị trí. - Button: Tìm kiếm | F10: Fail | G10: 21/04/2024 | H10: =B3 -> Việt | I10: Lỗi toàn bộ màn hình EV: https://drive.google.com/file/d/1dX5oLTWdXBTF5-arbtQp1kGrLOH8BzKb/view?usp=drive_link
B11: 1.2. Kiểm tra chức năng
A12: =IF(AND(E12=""),"","["&TEXT($B$1,"##")&"-"&TEXT(ROW()-9-COUNTBLANK($E$8:E11)+1,"##")&"]") -> [UC08-2] | B12: Kiểm tra chức năng tìm kiếm | C12: - Truy cập vào hệ thống http://34.143.239.189/ | D12: 1. Ứng viên vào mục "Tìm việc" 2. Ứng viên nhập thông tin vào các bộ lọc tìm kiếm 3. Bấm nút Tìm kiếm | E12: Hệ thống sẽ hiện thị danh sách các tin tuyển dụng kèm theo lựa chọn cho ứng viên bao gồm : “Chia sẻ ”, “Ứng tuyển ngay”, “xem chi tiết” | F12: N/A | G12: 21/04/2024 | H12: =B3 -> Việt | I12: Không có bộ lọc tìm kiếm, chờ fix [UC08-1]
A13: =IF(AND(E13=""),"","["&TEXT($B$1,"##")&"-"&TEXT(ROW()-9-COUNTBLANK($E$8:E12)+1,"##")&"]") -> [UC08-3] | B13: Kiểm tra chức năng xem chi tiết mô tả công việc | C13: - Truy cập vào hệ thống http://34.143.239.189/ | D13: 1. Ứng viên vào mục "Tìm việc" 2. Ứng viên nhập thông tin vào các bộ lọc tìm kiếm 3. Bấm nút Tìm kiếm 4. Chọn "Xem chi tiết" | E13: Hệ thống chuyển sang trang mô tả chi tiết về công việc | F13: Pass | G13: 21/04/2024 | H13: =B3 -> Việt
A14: =IF(AND(E14=""),"","["&TEXT($B$1,"##")&"-"&TEXT(ROW()-9-COUNTBLANK($E$8:E13)+1,"##")&"]") -> [UC08-4] | B14: Kiểm tra chức năng ứng tuyển | C14: - Truy cập vào hệ thống http://34.143.239.189/ | D14: 1. Ứng viên vào mục "Tìm việc" 2. Ứng viên nhập thông tin vào các bộ lọc tìm kiếm 3. Bấm nút Tìm kiếm 4. Chọn "Xem chi tiết" 5. Click vào ứng tuyển | E14: Hệ thống thông báo ứng tuyển thành công | F14: Fail | G14: 21/04/2024 | H14: =B3 -> Việt | I14: Lỗi không thể ứng tuyển EV: https://drive.google.com/file/d/1J3k0W3jXEwXriEWAdynV1912B11MN1D4/view?usp=drive_link
A15: =IF(AND(E15=""),"","["&TEXT($B$1,"##")&"-"&TEXT(ROW()-9-COUNTBLANK($E$8:E14)+1,"##")&"]") -> [UC08-5] | B15: Kiểm tra chức năng “Ứng tuyển ngay” trên đề mục của tin tuyển dụng. | C15: - Truy cập vào hệ thống http://34.143.239.189/ | D15: 1. Ứng viên vào mục "Tìm việc" 2. Click vào "Ứng tuyển ngay" | E15: Hệ thống thông báo ứng tuyển thành công | F15: Pass | G15: 21/04/2024 | H15: =B3 -> Việt
A16: =IF(AND(E16=""),"","["&TEXT($B$1,"##")&"-"&TEXT(ROW()-9-COUNTBLANK($E$8:E15)+1,"##")&"]") -> [UC08-6] | B16: Kiểm tra chức năng Chia sẻ | C16: - Truy cập vào hệ thống http://34.143.239.189/ | D16: 1. Ứng viên vào mục "Tìm việc" 2. Ứng viên nhập thông tin vào các bộ lọc tìm kiếm 3. Chọn "Chia sẻ' | E16: Hệ thống hiển thị đường link liên kết ra các mạng xã hội. | F16: Fail | G16: 21/04/2024 | H16: =B3 -> Việt | I16: Không thể click chia sẻ EV: https://drive.google.com/file/d/1CgT2pryAtdUkssQeIf3R_7st2y0trrWy/view?usp=drive_link

Sheet Chỉnh sửa hồ sơ ứng viên
A1: Item Test | B1: UC09
A2: Test requirement | B2: Ensure that all features listed below work properly without any errors when using the below browsers. - Edge in latest version - Google Chrome in latest version
A3: Tester | B3: Việt
A4: Pass | B4: Fail | C4: NT | D4: N/A | E4: Number of Test cases
A5: =COUNTIF(F:F,"Pass") -> 4 | B5: =COUNTIF(F:F,"Fail") -> 2 | C5: =COUNTIF(F:F,"Untested") -> 0 | D5: =COUNTIF(F:F,"N/A") -> 0 | E5: =SUM(A5:D5) -> 6
A6: % | B6: % | C6: % | D6: %
A8: ID | B8: Test Case Description | C8: Pre-condition | D8: Test Case Procedure | E8: Expected Output | F8: Result | G8: Test date | H8: Tester | I8: Note
B9: 1.1. Kiểm tra giao diện
A10: =IF(AND(E10=""),"","["&TEXT($B$1,"##")&"-"&TEXT(ROW()-9-COUNTBLANK($E$8:E9)+1,"##")&"]") -> [UC09-1] | B10: Kiểm tra tổng quan giao diện chỉnh sửa | C10: - Truy cập vào hệ thống http://34.143.239.189/ | D10: 1. Ứng viên vào mục “Thông tin cá nhân” 2. Ứng viên chọn mục “Hồ sơ” 3. Ứng viên chọn chỉnh sửa . | E10: Hiển thị danh sách các trường thông tin hiên tại của ứng viên. | F10: Pass | G10: 21/04/2024 | H10: =B3 -> Việt
A11: =IF(AND(E11=""),"","["&TEXT($B$1,"##")&"-"&TEXT(ROW()-9-COUNTBLANK($E$8:E10)+1,"##")&"]") -> [UC09-2] | B11: Kiểm tra chi tiết các textbox ở màn hình | C11: - Truy cập vào hệ thống http://34.143.239.189/ | D11: 1. Ứng viên vào mục “Thông tin cá nhân” 2. Ứng viên chọn mục “Hồ sơ” 3. Ứng viên chọn chỉnh sửa. 4. Nhập thông tin vào các textbox | E11: Cho phép nhập thông tin | F11: Pass | G11: 21/04/2024 | H11: =B3 -> Việt
